ERROR:root:[auto_mall] 오류: Traceback (most recent call last):
  File "/Users/choenamho/Documents/GitHub/main-project/Home.py", line 67, in <module>
    import A_auto_mall as auto
  File "/Users/choenamho/Documents/GitHub/main-project/A_auto_mall.py", line 38
    st.subheader("캐스퍼 모델 비교")
    ^^
IndentationError: expected an indented block after 'if' statement on line 37

ERROR:root:[auto_mall] 오류: Traceback (most recent call last):
  File "/Users/choenamho/Documents/GitHub/main-project/Home.py", line 68, in <module>
    auto.app()
  File "/Users/choenamho/Documents/GitHub/main-project/A_auto_mall.py", line 37, in app
    if selected_tab == "casper":  # 혹은 탭 이름이 'casper'로 되어 있는 경우
NameError: name 'selected_tab' is not defined

ERROR:root:[auto_mall] 오류: Traceback (most recent call last):
  File "/Users/choenamho/Documents/GitHub/main-project/Home.py", line 68, in <module>
    auto.app()
  File "/Users/choenamho/Documents/GitHub/main-project/A_auto_mall.py", line 37, in app
    if selected_tab == "casper":  # 혹은 탭 이름이 'casper'로 되어 있는 경우
NameError: name 'selected_tab' is not defined

ERROR:root:[auto_mall] 오류: Traceback (most recent call last):
  File "/Users/choenamho/Documents/GitHub/main-project/Home.py", line 67, in <module>
    import A_auto_mall as auto
  File "/Users/choenamho/Documents/GitHub/main-project/A_auto_mall.py", line 43
    st.image("https://casper.hyundai.com/_nuxt/img/img-lineup-ice.4aabfee.png", use_coluU==mn_width=True)
                                                                                ^^^^^^^^^^^^^^^^^^^^
SyntaxError: expression cannot contain assignment, perhaps you meant "=="?

ERROR:root:[auto_mall] 오류: Traceback (most recent call last):
  File "/Users/choenamho/Documents/GitHub/main-project/Home.py", line 68, in <module>
    auto.app()
  File "/Users/choenamho/Documents/GitHub/main-project/A_auto_mall.py", line 43, in app
    st.image("https://casper.hyundai.com/_nuxt/img/img-lineup-ice.4aabfee.png", U=True)
  File "/Users/choenamho/hi/lib/python3.10/site-packages/streamlit/runtime/metrics_util.py", line 410, in wrapped_func
    result = non_optional_func(*args, **kwargs)
TypeError: ImageMixin.image() got an unexpected keyword argument 'U'

ERROR:root:[auto_mall] 오류: Traceback (most recent call last):
  File "/Users/choenamho/Documents/GitHub/main-project/Home.py", line 68, in <module>
    auto.app()
  File "/Users/choenamho/Documents/GitHub/main-project/A_auto_mall.py", line 43, in app
    st.image("https://casper.hyundai.com/_nuxt/img/img-lineup-ice.4aabfee.png", USE=True)
  File "/Users/choenamho/hi/lib/python3.10/site-packages/streamlit/runtime/metrics_util.py", line 410, in wrapped_func
    result = non_optional_func(*args, **kwargs)
TypeError: ImageMixin.image() got an unexpected keyword argument 'USE'

ERROR:root:[auto_mall] 오류: Traceback (most recent call last):
  File "/Users/choenamho/Documents/GitHub/main-project/Home.py", line 68, in <module>
    auto.app()
  File "/Users/choenamho/Documents/GitHub/main-project/A_auto_mall.py", line 43, in app
    st.image("https://casper.hyundai.com/_nuxt/img/img-lineup-ice.4aabfee.png", use_container_width==True)
NameError: name 'use_container_width' is not defined

ERROR:root:[auto_mall] 오류: Traceback (most recent call last):
  File "/Users/choenamho/hi/lib/python3.10/site-packages/streamlit/elements/lib/image_utils.py", line 286, in image_to_url
    with open(image, "rb") as f:
FileNotFoundError: [Errno 2] No such file or directory: 'hhttps://casper.hyundai.com/_nuxt/img/trim-img-01.811d5ec.png'

During handling of the above exception, another exception occurred:

Traceback (most recent call last):
  File "/Users/choenamho/hi/lib/python3.10/site-packages/streamlit/runtime/memory_media_file_storage.py", line 163, in _read_file
    with open(filename, "rb") as f:
FileNotFoundError: [Errno 2] No such file or directory: 'hhttps://casper.hyundai.com/_nuxt/img/trim-img-01.811d5ec.png'

The above exception was the direct cause of the following exception:

Traceback (most recent call last):
  File "/Users/choenamho/Documents/GitHub/main-project/Home.py", line 68, in <module>
    auto.app()
  File "/Users/choenamho/Documents/GitHub/main-project/A_auto_mall.py", line 50, in app
    st.image("hhttps://casper.hyundai.com/_nuxt/img/trim-img-01.811d5ec.png", use_container_width=True)
  File "/Users/choenamho/hi/lib/python3.10/site-packages/streamlit/runtime/metrics_util.py", line 410, in wrapped_func
    result = non_optional_func(*args, **kwargs)
  File "/Users/choenamho/hi/lib/python3.10/site-packages/streamlit/elements/image.py", line 181, in image
    marshall_images(
  File "/Users/choenamho/hi/lib/python3.10/site-packages/streamlit/elements/lib/image_utils.py", line 439, in marshall_images
    proto_img.url = image_to_url(
  File "/Users/choenamho/hi/lib/python3.10/site-packages/streamlit/elements/lib/image_utils.py", line 298, in image_to_url
    url = runtime.get_instance().media_file_mgr.add(image, mimetype, image_id)
  File "/Users/choenamho/hi/lib/python3.10/site-packages/streamlit/runtime/media_file_manager.py", line 226, in add
    file_id = self._storage.load_and_get_id(
  File "/Users/choenamho/hi/lib/python3.10/site-packages/streamlit/runtime/memory_media_file_storage.py", line 114, in load_and_get_id
    file_data = self._read_file(path_or_data)
  File "/Users/choenamho/hi/lib/python3.10/site-packages/streamlit/runtime/memory_media_file_storage.py", line 166, in _read_file
    raise MediaFileStorageError(f"Error opening '{filename}'") from ex
streamlit.runtime.media_file_storage.MediaFileStorageError: Error opening 'hhttps://casper.hyundai.com/_nuxt/img/trim-img-01.811d5ec.png'

ERROR:root:[auto_mall] 오류: Traceback (most recent call last):
  File "/Users/choenamho/Documents/GitHub/main-project/Home.py", line 68, in <module>
    auto.app()
  File "/Users/choenamho/Documents/GitHub/main-project/A_auto_mall.py", line 36, in app
    with tabs[6]:
IndexError: tuple index out of range

ERROR:root:[auto_mall] 오류: Traceback (most recent call last):
  File "/Users/choenamho/Documents/GitHub/main-project/Home.py", line 67, in <module>
    import A_auto_mall as auto
  File "/Users/choenamho/Documents/GitHub/main-project/A_auto_mall.py", line 7
    st.markdown("오토몰: 고객 응대 화면"")
                               ^
SyntaxError: unterminated string literal (detected at line 7)

ERROR:root:[auto_mall] 오류: Traceback (most recent call last):
  File "/Users/choenamho/Documents/GitHub/main-project/Home.py", line 68, in <module>
    auto.app()
  File "/Users/choenamho/Documents/GitHub/main-project/A_auto_mall.py", line 36, in app
    with tabs[6]:
IndexError: tuple index out of range

ERROR:root:[auto_mall] 오류: Traceback (most recent call last):
  File "/Users/choenamho/Documents/GitHub/main-project/Home.py", line 68, in <module>
    auto.app()
  File "/Users/choenamho/Documents/GitHub/main-project/A_auto_mall.py", line 36, in app
    with tabs[6]:
IndexError: tuple index out of range

ERROR:root:[auto_mall] 오류: Traceback (most recent call last):
  File "/Users/choenamho/Documents/GitHub/main-project/Home.py", line 68, in <module>
    auto.app()
  File "/Users/choenamho/Documents/GitHub/main-project/A_auto_mall.py", line 36, in app
    with tabs[6]:
IndexError: tuple index out of range

ERROR:root:[auto_mall] 오류: Traceback (most recent call last):
  File "/Users/choenamho/Documents/GitHub/main-project/Home.py", line 68, in <module>
    auto.app()
  File "/Users/choenamho/Documents/GitHub/main-project/A_auto_mall.py", line 36, in app
    with tabs[6]:
IndexError: tuple index out of range

ERROR:root:[auto_mall] 오류: Traceback (most recent call last):
  File "/Users/choenamho/Documents/GitHub/main-project/Home.py", line 68, in <module>
    auto.app()
  File "/Users/choenamho/Documents/GitHub/main-project/A_auto_mall.py", line 36, in app
    with tabs[6]:
IndexError: tuple index out of range

ERROR:root:[auto_mall] 오류: Traceback (most recent call last):
  File "/Users/choenamho/Documents/GitHub/main-project/Home.py", line 67, in <module>
    import A_auto_mall as auto
  File "/Users/choenamho/Documents/GitHub/main-project/A_auto_mall.py", line 40
    st.subheader("캐스퍼 모델 비교")
    ^^
IndentationError: expected an indented block after 'with' statement on line 39

ERROR:root:[auto_mall] 오류: Traceback (most recent call last):
  File "/Users/choenamho/Documents/GitHub/main-project/Home.py", line 68, in <module>
    auto.app()
  File "/Users/choenamho/Documents/GitHub/main-project/A_auto_mall.py", line 36, in app
    with tabs[6]:
IndexError: tuple index out of range

ERROR:root:[auto_mall] 오류: Traceback (most recent call last):
  File "/Users/choenamho/Documents/GitHub/main-project/Home.py", line 68, in <module>
    auto.app()
  File "/Users/choenamho/Documents/GitHub/main-project/A_auto_mall.py", line 36, in app
    with tabs[6]:
IndexError: tuple index out of range

ERROR:root:[auto_mall] 오류: Traceback (most recent call last):
  File "/Users/choenamho/Documents/GitHub/main-project/Home.py", line 68, in <module>
    auto.app()
  File "/Users/choenamho/Documents/GitHub/main-project/A_auto_mall.py", line 36, in app
    with tabs[6]:
IndexError: tuple index out of range

ERROR:root:[auto_mall] 오류: Traceback (most recent call last):
  File "/Users/choenamho/Documents/GitHub/main-project/Home.py", line 68, in <module>
    auto.app()
  File "/Users/choenamho/Documents/GitHub/main-project/A_auto_mall.py", line 44, in app
    st.image("https://casper.hyundai.com/_nuxt/img/img-lineup-ice.4aabfee.png", idth=200)
  File "/Users/choenamho/hi/lib/python3.10/site-packages/streamlit/runtime/metrics_util.py", line 410, in wrapped_func
    result = non_optional_func(*args, **kwargs)
TypeError: ImageMixin.image() got an unexpected keyword argument 'idth'

ERROR:root:[auto_mall] 오류: Traceback (most recent call last):
  File "/Users/choenamho/Documents/GitHub/main-project/Home.py", line 68, in <module>
    auto.app()
  File "/Users/choenamho/Documents/GitHub/main-project/A_auto_mall.py", line 44, in app
    st.image("https://casper.hyundai.com/_nuxt/img/img-lineup-ice.4aabfee.png", ㅈidth=200)
  File "/Users/choenamho/hi/lib/python3.10/site-packages/streamlit/runtime/metrics_util.py", line 410, in wrapped_func
    result = non_optional_func(*args, **kwargs)
TypeError: ImageMixin.image() got an unexpected keyword argument 'ᄌidth'

ERROR:root:[auto_mall] 오류: Traceback (most recent call last):
  File "/Users/choenamho/Documents/GitHub/main-project/Home.py", line 67, in <module>
    import A_auto_mall as auto
  File "/Users/choenamho/Documents/GitHub/main-project/A_auto_mall.py", line 5, in <module>
    df = pd.read_csv("data/캐스퍼/casper_final.csv")
NameError: name 'pd' is not defined

ERROR:root:[auto_mall] 오류: Traceback (most recent call last):
  File "/Users/choenamho/Documents/GitHub/main-project/Home.py", line 67, in <module>
    import A_auto_mall as auto
  File "/Users/choenamho/Documents/GitHub/main-project/A_auto_mall.py", line 59
    st.subheader("캐스퍼 전체 라인업 보기")
    ^^
IndentationError: expected an indented block after 'with' statement on line 58

ERROR:root:[auto_mall] 오류: Traceback (most recent call last):
  File "/Users/choenamho/Documents/GitHub/main-project/Home.py", line 67, in <module>
    import A_auto_mall as auto
  File "/Users/choenamho/Documents/GitHub/main-project/A_auto_mall.py", line 5, in <module>
    df = pd.read_csv("data/캐스퍼/casper_final.csv")
NameError: name 'pd' is not defined

ERROR:root:[auto_mall] 오류: Traceback (most recent call last):
  File "/Users/choenamho/Documents/GitHub/main-project/Home.py", line 67, in <module>
    import A_auto_mall as auto
  File "/Users/choenamho/Documents/GitHub/main-project/A_auto_mall.py", line 5, in <module>
    df = pd.read_csv("data/캐스퍼/casper_final.csv")
NameError: name 'pd' is not defined

ERROR:root:[auto_mall] 오류: Traceback (most recent call last):
  File "/Users/choenamho/Documents/GitHub/main-project/Home.py", line 67, in <module>
    import A_auto_mall as auto
  File "/Users/choenamho/Documents/GitHub/main-project/A_auto_mall.py", line 5, in <module>
    df = pd.read_csv("data/캐스퍼/casper_final.csv")
NameError: name 'pd' is not defined

ERROR:root:[auto_mall] 오류: Traceback (most recent call last):
  File "/Users/choenamho/Documents/GitHub/main-project/Home.py", line 67, in <module>
    import A_auto_mall as auto
  File "/Users/choenamho/Documents/GitHub/main-project/A_auto_mall.py", line 6, in <module>
    df = pd.read_csv("data/캐스퍼/casper_final.csv")
  File "/Users/choenamho/hi/lib/python3.10/site-packages/pandas/io/parsers/readers.py", line 1026, in read_csv
    return _read(filepath_or_buffer, kwds)
  File "/Users/choenamho/hi/lib/python3.10/site-packages/pandas/io/parsers/readers.py", line 620, in _read
    parser = TextFileReader(filepath_or_buffer, **kwds)
  File "/Users/choenamho/hi/lib/python3.10/site-packages/pandas/io/parsers/readers.py", line 1620, in __init__
    self._engine = self._make_engine(f, self.engine)
  File "/Users/choenamho/hi/lib/python3.10/site-packages/pandas/io/parsers/readers.py", line 1880, in _make_engine
    self.handles = get_handle(
  File "/Users/choenamho/hi/lib/python3.10/site-packages/pandas/io/common.py", line 873, in get_handle
    handle = open(
FileNotFoundError: [Errno 2] No such file or directory: 'data/캐스퍼/casper_final.csv'

ERROR:root:[auto_mall] 오류: Traceback (most recent call last):
  File "/Users/choenamho/Documents/GitHub/main-project/Home.py", line 67, in <module>
    import A_auto_mall as auto
  File "/Users/choenamho/Documents/GitHub/main-project/A_auto_mall.py", line 6, in <module>
    df = pd.read_csv("data/캐스퍼/casper_final.csv")
  File "/Users/choenamho/hi/lib/python3.10/site-packages/pandas/io/parsers/readers.py", line 1026, in read_csv
    return _read(filepath_or_buffer, kwds)
  File "/Users/choenamho/hi/lib/python3.10/site-packages/pandas/io/parsers/readers.py", line 620, in _read
    parser = TextFileReader(filepath_or_buffer, **kwds)
  File "/Users/choenamho/hi/lib/python3.10/site-packages/pandas/io/parsers/readers.py", line 1620, in __init__
    self._engine = self._make_engine(f, self.engine)
  File "/Users/choenamho/hi/lib/python3.10/site-packages/pandas/io/parsers/readers.py", line 1880, in _make_engine
    self.handles = get_handle(
  File "/Users/choenamho/hi/lib/python3.10/site-packages/pandas/io/common.py", line 873, in get_handle
    handle = open(
FileNotFoundError: [Errno 2] No such file or directory: 'data/캐스퍼/casper_final.csv'

ERROR:root:[auto_mall] 오류: Traceback (most recent call last):
  File "/Users/choenamho/Documents/GitHub/main-project/Home.py", line 68, in <module>
    auto.app()
  File "/Users/choenamho/Documents/GitHub/main-project/A_auto_mall.py", line 62, in app
    render_cards(casper, "캐스퍼 모델")
  File "/Users/choenamho/Documents/GitHub/main-project/A_auto_mall.py", line 21, in render_cards
    st.image(item["img_url"], user)
NameError: name 'user' is not defined

ERROR:root:[auto_mall] 오류: Traceback (most recent call last):
  File "/Users/choenamho/Documents/GitHub/main-project/Home.py", line 67, in <module>
    import A_auto_mall as auto
  File "/Users/choenamho/Documents/GitHub/main-project/A_auto_mall.py", line 21
    st.image(item["img_url"], use_container_width=)
                                                  ^
SyntaxError: invalid syntax

ERROR:root:[auto_mall] 오류: Traceback (most recent call last):
  File "/Users/choenamho/Documents/GitHub/main-project/Home.py", line 68, in <module>
    auto.app()
  File "/Users/choenamho/Documents/GitHub/main-project/A_auto_mall.py", line 42, in app
    render_cards(casper, "캐스퍼 모델")
NameError: name 'render_cards' is not defined

ERROR:root:[auto_mall] 오류: Traceback (most recent call last):
  File "/Users/choenamho/Documents/GitHub/main-project/Home.py", line 67, in <module>
    import A_auto_mall as auto
  File "/Users/choenamho/Documents/GitHub/main-project/A_auto_mall.py", line 43
    casper = df[df["차종"].str.contains("캐스퍼", na=False) & ~df["차종"].str.contains("일렉트", na=False)]
    ^^^^^^
IndentationError: expected an indented block after 'with' statement on line 41

ERROR:root:[auto_mall] 오류: Traceback (most recent call last):
  File "/Users/choenamho/Documents/GitHub/main-project/Home.py", line 67, in <module>
    import A_auto_mall as auto
  File "/Users/choenamho/Documents/GitHub/main-project/A_auto_mall.py", line 46
    st.markdown("### 🔵 캐스퍼 모델")
    ^^
IndentationError: expected an indented block after 'with' statement on line 41

ERROR:root:[auto_mall] 오류: Traceback (most recent call last):
  File "/Users/choenamho/Documents/GitHub/main-project/Home.py", line 67, in <module>
    import A_auto_mall as auto
  File "/Users/choenamho/Documents/GitHub/main-project/A_auto_mall.py", line 6
    casper = df[df["차종"].str.contains("캐스퍼", na=False) & ~df["차종"].str.contains("일렉트", na=False)]
IndentationError: unexpected indent

ERROR:root:[auto_mall] 오류: Traceback (most recent call last):
  File "/Users/choenamho/Documents/GitHub/main-project/Home.py", line 67, in <module>
    import A_auto_mall as auto
  File "/Users/choenamho/Documents/GitHub/main-project/A_auto_mall.py", line 47
    st.markdown("### 🔵 캐스퍼 모델")
    ^^
IndentationError: expected an indented block after 'with' statement on line 42

ERROR:root:[auto_mall] 오류: Traceback (most recent call last):
  File "/Users/choenamho/Documents/GitHub/main-project/Home.py", line 67, in <module>
    import A_auto_mall as auto
  File "/Users/choenamho/Documents/GitHub/main-project/A_auto_mall.py", line 49
    st.markdown("### 🔵 캐스퍼 모델")
    ^^
IndentationError: expected an indented block after 'with' statement on line 44

ERROR:root:[auto_mall] 오류: Traceback (most recent call last):
  File "/Users/choenamho/Documents/GitHub/main-project/Home.py", line 67, in <module>
    import A_auto_mall as auto
  File "/Users/choenamho/Documents/GitHub/main-project/A_auto_mall.py", line 48
    st.markdown("### 🔵 캐스퍼 모델")
    ^^
IndentationError: expected an indented block after 'with' statement on line 43

ERROR:root:[auto_mall] 오류: Traceback (most recent call last):
  File "/Users/choenamho/Documents/GitHub/main-project/Home.py", line 67, in <module>
    import A_auto_mall as auto
  File "/Users/choenamho/Documents/GitHub/main-project/A_auto_mall.py", line 48
    st.markdown("### 🔵 캐스퍼 모델")
    ^^
IndentationError: expected an indented block after 'with' statement on line 43

ERROR:root:[auto_mall] 오류: Traceback (most recent call last):
  File "/Users/choenamho/Documents/GitHub/main-project/Home.py", line 67, in <module>
    import A_auto_mall as auto
  File "/Users/choenamho/Documents/GitHub/main-project/A_auto_mall.py", line 48
    st.markdown("### 🔵 캐스퍼 모델")
    ^^
IndentationError: expected an indented block after 'with' statement on line 43

ERROR:root:[auto_mall] 오류: Traceback (most recent call last):
  File "/Users/choenamho/Documents/GitHub/main-project/Home.py", line 67, in <module>
    import A_auto_mall as auto
  File "/Users/choenamho/Documents/GitHub/main-project/A_auto_mall.py", line 6, in <module>
    df = pd.read_csv("data/캐스퍼/casper_final.csv")
  File "/Users/choenamho/hi/lib/python3.10/site-packages/pandas/io/parsers/readers.py", line 1026, in read_csv
    return _read(filepath_or_buffer, kwds)
  File "/Users/choenamho/hi/lib/python3.10/site-packages/pandas/io/parsers/readers.py", line 620, in _read
    parser = TextFileReader(filepath_or_buffer, **kwds)
  File "/Users/choenamho/hi/lib/python3.10/site-packages/pandas/io/parsers/readers.py", line 1620, in __init__
    self._engine = self._make_engine(f, self.engine)
  File "/Users/choenamho/hi/lib/python3.10/site-packages/pandas/io/parsers/readers.py", line 1880, in _make_engine
    self.handles = get_handle(
  File "/Users/choenamho/hi/lib/python3.10/site-packages/pandas/io/common.py", line 873, in get_handle
    handle = open(
FileNotFoundError: [Errno 2] No such file or directory: 'data/캐스퍼/casper_final.csv'

ERROR:root:[auto_mall] 오류: Traceback (most recent call last):
  File "/Users/choenamho/Documents/GitHub/main-project/Home.py", line 67, in <module>
    import A_auto_mall as auto
  File "/Users/choenamho/Documents/GitHub/main-project/A_auto_mall.py", line 6, in <module>
    df = pd.read_csv("data/캐스퍼/casper_final.csv")
  File "/Users/choenamho/hi/lib/python3.10/site-packages/pandas/io/parsers/readers.py", line 1026, in read_csv
    return _read(filepath_or_buffer, kwds)
  File "/Users/choenamho/hi/lib/python3.10/site-packages/pandas/io/parsers/readers.py", line 620, in _read
    parser = TextFileReader(filepath_or_buffer, **kwds)
  File "/Users/choenamho/hi/lib/python3.10/site-packages/pandas/io/parsers/readers.py", line 1620, in __init__
    self._engine = self._make_engine(f, self.engine)
  File "/Users/choenamho/hi/lib/python3.10/site-packages/pandas/io/parsers/readers.py", line 1880, in _make_engine
    self.handles = get_handle(
  File "/Users/choenamho/hi/lib/python3.10/site-packages/pandas/io/common.py", line 873, in get_handle
    handle = open(
FileNotFoundError: [Errno 2] No such file or directory: 'data/캐스퍼/casper_final.csv'

ERROR:root:[auto_mall] 오류: Traceback (most recent call last):
  File "/Users/choenamho/Documents/GitHub/main-project/Home.py", line 67, in <module>
    import A_auto_mall as auto
  File "/Users/choenamho/Documents/GitHub/main-project/A_auto_mall.py", line 6, in <module>
    df = pd.read_csv("data/캐스퍼/casper_final.csv")
  File "/Users/choenamho/hi/lib/python3.10/site-packages/pandas/io/parsers/readers.py", line 1026, in read_csv
    return _read(filepath_or_buffer, kwds)
  File "/Users/choenamho/hi/lib/python3.10/site-packages/pandas/io/parsers/readers.py", line 620, in _read
    parser = TextFileReader(filepath_or_buffer, **kwds)
  File "/Users/choenamho/hi/lib/python3.10/site-packages/pandas/io/parsers/readers.py", line 1620, in __init__
    self._engine = self._make_engine(f, self.engine)
  File "/Users/choenamho/hi/lib/python3.10/site-packages/pandas/io/parsers/readers.py", line 1880, in _make_engine
    self.handles = get_handle(
  File "/Users/choenamho/hi/lib/python3.10/site-packages/pandas/io/common.py", line 873, in get_handle
    handle = open(
FileNotFoundError: [Errno 2] No such file or directory: 'data/캐스퍼/casper_final.csv'

ERROR:root:[auto_mall] 오류: Traceback (most recent call last):
  File "/Users/choenamho/Documents/GitHub/main-project/Home.py", line 67, in <module>
    import A_auto_mall as auto
  File "/Users/choenamho/Documents/GitHub/main-project/A_auto_mall.py", line 6, in <module>
    df = pd.read_csv("data/캐스퍼/casper_final.csv")
  File "/Users/choenamho/hi/lib/python3.10/site-packages/pandas/io/parsers/readers.py", line 1026, in read_csv
    return _read(filepath_or_buffer, kwds)
  File "/Users/choenamho/hi/lib/python3.10/site-packages/pandas/io/parsers/readers.py", line 620, in _read
    parser = TextFileReader(filepath_or_buffer, **kwds)
  File "/Users/choenamho/hi/lib/python3.10/site-packages/pandas/io/parsers/readers.py", line 1620, in __init__
    self._engine = self._make_engine(f, self.engine)
  File "/Users/choenamho/hi/lib/python3.10/site-packages/pandas/io/parsers/readers.py", line 1880, in _make_engine
    self.handles = get_handle(
  File "/Users/choenamho/hi/lib/python3.10/site-packages/pandas/io/common.py", line 873, in get_handle
    handle = open(
FileNotFoundError: [Errno 2] No such file or directory: 'data/캐스퍼/casper_final.csv'

ERROR:root:[auto_mall] 오류: Traceback (most recent call last):
  File "/Users/choenamho/Documents/GitHub/main-project/Home.py", line 67, in <module>
    import A_auto_mall as auto
  File "/Users/choenamho/Documents/GitHub/main-project/A_auto_mall.py", line 6, in <module>
    df = pd.read_csv("data/캐스퍼/casper_final.csv")
  File "/Users/choenamho/hi/lib/python3.10/site-packages/pandas/io/parsers/readers.py", line 1026, in read_csv
    return _read(filepath_or_buffer, kwds)
  File "/Users/choenamho/hi/lib/python3.10/site-packages/pandas/io/parsers/readers.py", line 620, in _read
    parser = TextFileReader(filepath_or_buffer, **kwds)
  File "/Users/choenamho/hi/lib/python3.10/site-packages/pandas/io/parsers/readers.py", line 1620, in __init__
    self._engine = self._make_engine(f, self.engine)
  File "/Users/choenamho/hi/lib/python3.10/site-packages/pandas/io/parsers/readers.py", line 1880, in _make_engine
    self.handles = get_handle(
  File "/Users/choenamho/hi/lib/python3.10/site-packages/pandas/io/common.py", line 873, in get_handle
    handle = open(
FileNotFoundError: [Errno 2] No such file or directory: 'data/캐스퍼/casper_final.csv'

ERROR:root:[auto_mall] 오류: Traceback (most recent call last):
  File "/Users/choenamho/Documents/GitHub/main-project/Home.py", line 67, in <module>
    import A_auto_mall as auto
  File "/Users/choenamho/Documents/GitHub/main-project/A_auto_mall.py", line 6, in <module>
    df = pd.read_csv("data/캐스퍼/casper_final.csv")
  File "/Users/choenamho/hi/lib/python3.10/site-packages/pandas/io/parsers/readers.py", line 1026, in read_csv
    return _read(filepath_or_buffer, kwds)
  File "/Users/choenamho/hi/lib/python3.10/site-packages/pandas/io/parsers/readers.py", line 620, in _read
    parser = TextFileReader(filepath_or_buffer, **kwds)
  File "/Users/choenamho/hi/lib/python3.10/site-packages/pandas/io/parsers/readers.py", line 1620, in __init__
    self._engine = self._make_engine(f, self.engine)
  File "/Users/choenamho/hi/lib/python3.10/site-packages/pandas/io/parsers/readers.py", line 1880, in _make_engine
    self.handles = get_handle(
  File "/Users/choenamho/hi/lib/python3.10/site-packages/pandas/io/common.py", line 873, in get_handle
    handle = open(
FileNotFoundError: [Errno 2] No such file or directory: 'data/캐스퍼/casper_final.csv'

ERROR:root:[auto_mall] 오류: Traceback (most recent call last):
  File "/Users/choenamho/Documents/GitHub/main-project/Home.py", line 68, in <module>
    auto.app()
  File "/Users/choenamho/Documents/GitHub/main-project/A_auto_mall.py", line 66, in app
    st.image(item["img_url"], use_cwidth=220)
  File "/Users/choenamho/hi/lib/python3.10/site-packages/streamlit/runtime/metrics_util.py", line 410, in wrapped_func
    result = non_optional_func(*args, **kwargs)
TypeError: ImageMixin.image() got an unexpected keyword argument 'use_cwidth'

ERROR:root:[auto_mall] 오류: Traceback (most recent call last):
  File "/Users/choenamho/Documents/GitHub/main-project/Home.py", line 67, in <module>
    import A_auto_mall as auto
  File "/Users/choenamho/Documents/GitHub/main-project/A_auto_mall.py", line 66
    st.image(item["img_url"], use_container_width=width=220)
                                                       ^
SyntaxError: invalid syntax

ERROR:root:[auto_mall] 오류: Traceback (most recent call last):
  File "/Users/choenamho/Documents/GitHub/main-project/Home.py", line 68, in <module>
    auto.app()
  File "/Users/choenamho/Documents/GitHub/main-project/A_auto_mall.py", line 66, in app
    st.image(item["img_url"], use_container_width=width)
NameError: name 'width' is not defined

ERROR:root:[auto_mall] 오류: Traceback (most recent call last):
  File "/Users/choenamho/Documents/GitHub/main-project/Home.py", line 68, in <module>
    auto.app()
  File "/Users/choenamho/Documents/GitHub/main-project/A_auto_mall.py", line 66, in app
    st.image(item["img_url"], use_container_width=wT)
NameError: name 'wT' is not defined

ERROR:root:[auto_mall] 오류: Traceback (most recent call last):
  File "/Users/choenamho/Documents/GitHub/main-project/Home.py", line 67, in <module>
    import A_auto_mall as auto
  File "/Users/choenamho/Documents/GitHub/main-project/A_auto_mall.py", line 43
    st.subheader("캐스퍼 전체 라인업 보기")
    ^^
IndentationError: expected an indented block after 'with' statement on line 42

ERROR:root:[auto_mall] 오류: Traceback (most recent call last):
  File "/Users/choenamho/Documents/GitHub/main-project/Home.py", line 67, in <module>
    import A_auto_mall as auto
  File "/Users/choenamho/Documents/GitHub/main-project/A_auto_mall.py", line 46
    casper = df[df["차종"].str.contains("캐스퍼", na=False) & ~df["차종"].str.contains("일렉트", na=False)]
IndentationError: unexpected indent

ERROR:root:[auto_mall] 오류: Traceback (most recent call last):
  File "/Users/choenamho/Documents/GitHub/main-project/Home.py", line 67, in <module>
    import A_auto_mall as auto
  File "/Users/choenamho/Documents/GitHub/main-project/A_auto_mall.py", line 46
    casper = df[df["차종"].str.contains("캐스퍼", na=False) & ~df["차종"].str.contains("일렉트", na=False)]
IndentationError: unexpected indent

ERROR:root:[auto_mall] 오류: Traceback (most recent call last):
  File "/Users/choenamho/Documents/GitHub/main-project/Home.py", line 67, in <module>
    import A_auto_mall as auto
  File "/Users/choenamho/Documents/GitHub/main-project/A_auto_mall.py", line 46
    casper = df[df["차종"].str.contains("캐스퍼", na=False) & ~df["차종"].str.contains("일렉트", na=False)]
                                                                                                 ^
IndentationError: unindent does not match any outer indentation level

ERROR:root:[auto_mall] 오류: Traceback (most recent call last):
  File "/Users/choenamho/Documents/GitHub/main-project/Home.py", line 67, in <module>
    import A_auto_mall as auto
  File "/Users/choenamho/Documents/GitHub/main-project/A_auto_mall.py", line 43
    st.subheader("캐스퍼 전체 라인업 보기")
    ^^
IndentationError: expected an indented block after 'with' statement on line 42

ERROR:root:[auto_mall] 오류: Traceback (most recent call last):
  File "/Users/choenamho/Documents/GitHub/main-project/Home.py", line 68, in <module>
    auto.app()
  File "/Users/choenamho/Documents/GitHub/main-project/A_auto_mall.py", line 67, in app
    casper_html = generate_html_table(casper_compare.fillna(""))
NameError: name 'generate_html_table' is not defined

ERROR:root:[auto_mall] 오류: Traceback (most recent call last):
  File "/Users/choenamho/Documents/GitHub/main-project/Home.py", line 67, in <module>
    import A_auto_mall as auto
  File "/Users/choenamho/Documents/GitHub/main-project/A_auto_mall.py", line 90
    col1, col2, col3 = 
                       ^
SyntaxError: invalid syntax

ERROR:root:[auto_mall] 오류: Traceback (most recent call last):
  File "/Users/choenamho/Documents/GitHub/main-project/Home.py", line 68, in <module>
    auto.app()
  File "/Users/choenamho/Documents/GitHub/main-project/A_auto_mall.py", line 90, in app
    col1, col2, col3 = cu
NameError: name 'cu' is not defined

ERROR:root:[auto_mall] 오류: Traceback (most recent call last):
  File "/Users/choenamho/Documents/GitHub/main-project/Home.py", line 68, in <module>
    auto.app()
  File "/Users/choenamho/Documents/GitHub/main-project/A_auto_mall.py", line 90, in app
    col1, col2, col3 = col
UnboundLocalError: local variable 'col' referenced before assignment

ERROR:root:[auto_mall] 오류: Traceback (most recent call last):
  File "/Users/choenamho/Documents/GitHub/main-project/Home.py", line 68, in <module>
    auto.app()
  File "/Users/choenamho/Documents/GitHub/main-project/A_auto_mall.py", line 90, in app
    col1, col2, col3 = w
NameError: name 'w' is not defined

ERROR:root:[auto_mall] 오류: Traceback (most recent call last):
  File "/Users/choenamho/Documents/GitHub/main-project/Home.py", line 67, in <module>
    import A_auto_mall as auto
  File "/Users/choenamho/Documents/GitHub/main-project/A_auto_mall.py", line 90
    col1, col2, col3 = with c
                       ^^^^
SyntaxError: invalid syntax

ERROR:root:[auto_mall] 오류: Traceback (most recent call last):
  File "/Users/choenamho/Documents/GitHub/main-project/Home.py", line 67, in <module>
    import A_auto_mall as auto
  File "/Users/choenamho/Documents/GitHub/main-project/A_auto_mall.py", line 90
    col1, col2, col3 = with co
                       ^^^^
SyntaxError: invalid syntax

ERROR:root:[auto_mall] 오류: Traceback (most recent call last):
  File "/Users/choenamho/Documents/GitHub/main-project/Home.py", line 67, in <module>
    import A_auto_mall as auto
  File "/Users/choenamho/Documents/GitHub/main-project/A_auto_mall.py", line 90
    col1, col2, col3 = with col
                       ^^^^
SyntaxError: invalid syntax

ERROR:root:[auto_mall] 오류: Traceback (most recent call last):
  File "/Users/choenamho/Documents/GitHub/main-project/Home.py", line 67, in <module>
    import A_auto_mall as auto
  File "/Users/choenamho/Documents/GitHub/main-project/A_auto_mall.py", line 90
    col1, col2, col3 = 
                       ^
SyntaxError: invalid syntax

ERROR:root:[auto_mall] 오류: Traceback (most recent call last):
  File "/Users/choenamho/Documents/GitHub/main-project/Home.py", line 68, in <module>
    auto.app()
  File "/Users/choenamho/Documents/GitHub/main-project/A_auto_mall.py", line 90, in app
    col1, col2, col3 = st.columns([1.5,1,1,1,1])
ValueError: too many values to unpack (expected 3)

ERROR:root:[auto_mall] 오류: Traceback (most recent call last):
  File "/Users/choenamho/Documents/GitHub/main-project/Home.py", line 67, in <module>
    import A_auto_mall as auto
  File "/Users/choenamho/Documents/GitHub/main-project/A_auto_mall.py", line 90
    col1, col2, col3 = st.columns([1.5,,1,1,1])
                                       ^
SyntaxError: invalid syntax

ERROR:root:[auto_mall] 오류: Traceback (most recent call last):
  File "/Users/choenamho/Documents/GitHub/main-project/Home.py", line 67, in <module>
    import A_auto_mall as auto
  File "/Users/choenamho/Documents/GitHub/main-project/A_auto_mall.py", line 91
    with col1
             ^
SyntaxError: expected ':'

ERROR:root:[auto_mall] 오류: Traceback (most recent call last):
  File "/Users/choenamho/Documents/GitHub/main-project/Home.py", line 67, in <module>
    import A_auto_mall as auto
  File "/Users/choenamho/Documents/GitHub/main-project/A_auto_mall.py", line 94
    st.markdown("### 캐스퍼 ")
    ^^
IndentationError: expected an indented block after 'with' statement on line 91

ERROR:root:[auto_mall] 오류: Traceback (most recent call last):
  File "/Users/choenamho/Documents/GitHub/main-project/Home.py", line 67, in <module>
    import A_auto_mall as auto
  File "/Users/choenamho/Documents/GitHub/main-project/A_auto_mall.py", line 96
    st.markdown("### 캐스퍼 ")
    ^^
IndentationError: expected an indented block after 'with' statement on line 94

ERROR:root:[auto_mall] 오류: Traceback (most recent call last):
  File "/Users/choenamho/Documents/GitHub/main-project/Home.py", line 67, in <module>
    import A_auto_mall as auto
  File "/Users/choenamho/Documents/GitHub/main-project/A_auto_mall.py", line 96
    st.markdown("### 캐스퍼 ")
    ^^
IndentationError: expected an indented block after 'with' statement on line 94

ERROR:root:[auto_mall] 오류: Traceback (most recent call last):
  File "/Users/choenamho/Documents/GitHub/main-project/Home.py", line 67, in <module>
    import A_auto_mall as auto
  File "/Users/choenamho/Documents/GitHub/main-project/A_auto_mall.py", line 96
    st.markdown("### 캐스퍼 ")
    ^^
IndentationError: expected an indented block after 'with' statement on line 94

ERROR:root:[auto_mall] 오류: Traceback (most recent call last):
  File "/Users/choenamho/Documents/GitHub/main-project/Home.py", line 67, in <module>
    import A_auto_mall as auto
  File "/Users/choenamho/Documents/GitHub/main-project/A_auto_mall.py", line 96
    st.markdown("### 캐스퍼 ")
    ^^
IndentationError: expected an indented block after 'with' statement on line 94

ERROR:root:[auto_mall] 오류: Traceback (most recent call last):
  File "/Users/choenamho/Documents/GitHub/main-project/Home.py", line 67, in <module>
    import A_auto_mall as auto
  File "/Users/choenamho/Documents/GitHub/main-project/A_auto_mall.py", line 96
    st.markdown("### 캐스퍼 ")
    ^^
IndentationError: expected an indented block after 'with' statement on line 94

ERROR:root:[auto_mall] 오류: Traceback (most recent call last):
  File "/Users/choenamho/Documents/GitHub/main-project/Home.py", line 67, in <module>
    import A_auto_mall as auto
  File "/Users/choenamho/Documents/GitHub/main-project/A_auto_mall.py", line 104
    st.markdown(f: {item['트림명']}")
                                ^
SyntaxError: unterminated string literal (detected at line 104)

ERROR:root:[auto_mall] 오류: Traceback (most recent call last):
  File "/Users/choenamho/Documents/GitHub/main-project/Home.py", line 67, in <module>
    import A_auto_mall as auto
  File "/Users/choenamho/Documents/GitHub/main-project/A_auto_mall.py", line 104
    st.markdown(f"": {item['트림명']}")
                                  ^
SyntaxError: unterminated string literal (detected at line 104)

ERROR:root:[auto_mall] 오류: Traceback (most recent call last):
  File "/Users/choenamho/Documents/GitHub/main-project/Home.py", line 67, in <module>
    import A_auto_mall as auto
  File "/Users/choenamho/Documents/GitHub/main-project/A_auto_mall.py", line 104
    st.markdown(f: {item['트림명']}")
                                ^
SyntaxError: unterminated string literal (detected at line 104)

ERROR:root:[auto_mall] 오류: Traceback (most recent call last):
  File "/Users/choenamho/Documents/GitHub/main-project/Home.py", line 67, in <module>
    import A_auto_mall as auto
  File "/Users/choenamho/Documents/GitHub/main-project/A_auto_mall.py", line 104
    st.markdown(f"": {item['트림명']}")
                                  ^
SyntaxError: unterminated string literal (detected at line 104)

ERROR:root:[auto_mall] 오류: Traceback (most recent call last):
  File "/Users/choenamho/Documents/GitHub/main-project/Home.py", line 67, in <module>
    import A_auto_mall as auto
  File "/Users/choenamho/Documents/GitHub/main-project/A_auto_mall.py", line 132
    if st.button("← 메인으로 돌아가기"):
    ^^
IndentationError: expected an indented block after 'with' statement on line 130

ERROR:root:[auto_mall] 오류: Traceback (most recent call last):
  File "/Users/choenamho/Documents/GitHub/main-project/Home.py", line 67, in <module>
    import A_auto_mall as auto
  File "/Users/choenamho/Documents/GitHub/main-project/A_auto_mall.py", line 131
    
    ^
IndentationError: expected an indented block after 'with' statement on line 130

ERROR:root:[auto_mall] 오류: Traceback (most recent call last):
  File "/Users/choenamho/Documents/GitHub/main-project/Home.py", line 68, in <module>
    auto.app()
  File "/Users/choenamho/Documents/GitHub/main-project/A_auto_mall.py", line 131, in app
    paxs
NameError: name 'paxs' is not defined

ERROR:root:[auto_mall] 오류: Traceback (most recent call last):
  File "/Users/choenamho/Documents/GitHub/main-project/Home.py", line 67, in <module>
    import A_auto_mall as auto
  File "/Users/choenamho/Documents/GitHub/main-project/A_auto_mall.py", line 63
    if st.button("← 메인으로 돌아가기"):
IndentationError: unexpected indent

ERROR:root:[auto_mall] 오류: Traceback (most recent call last):
  File "/Users/choenamho/Documents/GitHub/main-project/Home.py", line 67, in <module>
    import A_auto_mall as auto
  File "/Users/choenamho/Documents/GitHub/main-project/A_auto_mall.py", line 64
    st.session_state.current_page = "home"
    ^^
IndentationError: expected an indented block after 'if' statement on line 63

ERROR:root:[auto_mall] 오류: Traceback (most recent call last):
  File "/Users/choenamho/Documents/GitHub/main-project/Home.py", line 67, in <module>
    import A_auto_mall as auto
  File "/Users/choenamho/Documents/GitHub/main-project/A_auto_mall.py", line 54
    if st.button("← 메인으로 돌아가기"):
IndentationError: unexpected indent

ERROR:root:[auto_mall] 오류: Traceback (most recent call last):
  File "/Users/choenamho/Documents/GitHub/main-project/Home.py", line 67, in <module>
    import A_auto_mall as auto
  File "/Users/choenamho/Documents/GitHub/main-project/A_auto_mall.py", line 53
    if st.button("← H):
                 ^
SyntaxError: unterminated string literal (detected at line 53)

ERROR:root:[auto_mall] 오류: Traceback (most recent call last):
  File "/Users/choenamho/Documents/GitHub/main-project/Home.py", line 67, in <module>
    import A_auto_mall as auto
  File "/Users/choenamho/Documents/GitHub/main-project/A_auto_mall.py", line 53
    if st.button("← HO):
                 ^
SyntaxError: unterminated string literal (detected at line 53)

ERROR:root:[auto_mall] 오류: Traceback (most recent call last):
  File "/Users/choenamho/Documents/GitHub/main-project/Home.py", line 67, in <module>
    import A_auto_mall as auto
  File "/Users/choenamho/Documents/GitHub/main-project/A_auto_mall.py", line 136
    이름 = st.text_input("이름")
                            ^
IndentationError: unindent does not match any outer indentation level

ERROR:root:[auto_mall] 오류: Traceback (most recent call last):
  File "/Users/choenamho/Documents/GitHub/main-project/Home.py", line 67, in <module>
    import A_auto_mall as auto
  File "/Users/choenamho/Documents/GitHub/main-project/A_auto_mall.py", line 96
    car = st.session_state["선택차량"]
IndentationError: expected an indented block after 'if' statement on line 95

ERROR:root:[auto_mall] 오류: Traceback (most recent call last):
  File "/Users/choenamho/Documents/GitHub/main-project/Home.py", line 67, in <module>
    import A_auto_mall as auto
  File "/Users/choenamho/Documents/GitHub/main-project/A_auto_mall.py", line 96
    car = st.session_state["선택차량"]
    ^^^
IndentationError: expected an indented block after 'if' statement on line 95

ERROR:root:[auto_mall] 오류: Traceback (most recent call last):
  File "/Users/choenamho/Documents/GitHub/main-project/Home.py", line 67, in <module>
    import A_auto_mall as auto
  File "/Users/choenamho/Documents/GitHub/main-project/A_auto_mall.py", line 96
    car = st.session_state["선택차량"]
    ^^^
IndentationError: expected an indented block after 'if' statement on line 95

ERROR:root:[auto_mall] 오류: Traceback (most recent call last):
  File "/Users/choenamho/Documents/GitHub/main-project/Home.py", line 67, in <module>
    import A_auto_mall as auto
  File "/Users/choenamho/Documents/GitHub/main-project/A_auto_mall.py", line 107
    with col2:
IndentationError: expected an indented block after 'with' statement on line 106

ERROR:root:[auto_mall] 오류: Traceback (most recent call last):
  File "/Users/choenamho/Documents/GitHub/main-project/Home.py", line 67, in <module>
    import A_auto_mall as auto
  File "/Users/choenamho/Documents/GitHub/main-project/A_auto_mall.py", line 107
    with col2:
IndentationError: expected an indented block after 'with' statement on line 106

ERROR:root:[auto_mall] 오류: Traceback (most recent call last):
  File "/Users/choenamho/Documents/GitHub/main-project/Home.py", line 67, in <module>
    import A_auto_mall as auto
  File "/Users/choenamho/Documents/GitHub/main-project/A_auto_mall.py", line 107
    with col2:
    ^^^^
IndentationError: expected an indented block after 'with' statement on line 106

ERROR:root:[auto_mall] 오류: Traceback (most recent call last):
  File "/Users/choenamho/Documents/GitHub/main-project/Home.py", line 67, in <module>
    import A_auto_mall as auto
  File "/Users/choenamho/Documents/GitHub/main-project/A_auto_mall.py", line 95
    if "선택차량" in st.session_state:
IndentationError: expected an indented block after 'with' statement on line 94

ERROR:root:[auto_mall] 오류: Traceback (most recent call last):
  File "/Users/choenamho/Documents/GitHub/main-project/Home.py", line 67, in <module>
    import A_auto_mall as auto
  File "/Users/choenamho/Documents/GitHub/main-project/A_auto_mall.py", line 95
    if "선택차량" in st.session_state:
    ^^
IndentationError: expected an indented block after 'with' statement on line 94

ERROR:root:[auto_mall] 오류: Traceback (most recent call last):
  File "/Users/choenamho/Documents/GitHub/main-project/Home.py", line 67, in <module>
    import A_auto_mall as auto
  File "/Users/choenamho/Documents/GitHub/main-project/A_auto_mall.py", line 114
    st.markdown(f"- {col}: {value}")current_page = "판매 등록"
                                    ^^^^^^^^^^^^
SyntaxError: invalid syntax

ERROR:root:[auto_mall] 오류: Traceback (most recent call last):
  File "/Users/choenamho/Documents/GitHub/main-project/Home.py", line 67, in <module>
    import A_auto_mall as auto
  File "/Users/choenamho/Documents/GitHub/main-project/A_auto_mall.py", line 95
    if "선택차량" in st.session_state:
IndentationError: expected an indented block after 'with' statement on line 94

ERROR:root:[auto_mall] 오류: Traceback (most recent call last):
  File "/Users/choenamho/Documents/GitHub/main-project/Home.py", line 67, in <module>
    import A_auto_mall as auto
  File "/Users/choenamho/Documents/GitHub/main-project/A_auto_mall.py", line 95, in <module>
    with col1:
NameError: name 'col1' is not defined

ERROR:root:[auto_mall] 오류: Traceback (most recent call last):
  File "/Users/choenamho/Documents/GitHub/main-project/Home.py", line 68, in <module>
    auto.app()
  File "/Users/choenamho/Documents/GitHub/main-project/A_auto_mall.py", line 96, in app
    with col1:
NameError: name 'col1' is not defined

ERROR:root:[auto_mall] 오류: Traceback (most recent call last):
  File "/Users/choenamho/Documents/GitHub/main-project/Home.py", line 67, in <module>
    import A_auto_mall as auto
  File "/Users/choenamho/Documents/GitHub/main-project/A_auto_mall.py", line 94
    col1, col2, col3 = st.columns([1,3,1])
IndentationError: unexpected indent

ERROR:root:[auto_mall] 오류: Traceback (most recent call last):
  File "/Users/choenamho/Documents/GitHub/main-project/Home.py", line 68, in <module>
    auto.app()
  File "/Users/choenamho/Documents/GitHub/main-project/A_auto_mall.py", line 53, in app
    col1, col2, col3 = st.columns([41])
ValueError: not enough values to unpack (expected 3, got 1)

ERROR:root:[auto_mall] 오류: Traceback (most recent call last):
  File "/Users/choenamho/Documents/GitHub/main-project/Home.py", line 68, in <module>
    auto.app()
  File "/Users/choenamho/Documents/GitHub/main-project/A_auto_mall.py", line 53, in app
    col1, col2, col3 = st.columns([4,1])
ValueError: not enough values to unpack (expected 3, got 2)

ERROR:root:[auto_mall] 오류: Traceback (most recent call last):
  File "/Users/choenamho/Documents/GitHub/main-project/Home.py", line 67, in <module>
    import A_auto_mall as auto
  File "/Users/choenamho/Documents/GitHub/main-project/A_auto_mall.py", line 55
    col1:
         ^
SyntaxError: invalid syntax

ERROR:root:[auto_mall] 오류: Traceback (most recent call last):
  File "/Users/choenamho/Documents/GitHub/main-project/Home.py", line 67, in <module>
    import A_auto_mall as auto
  File "/Users/choenamho/Documents/GitHub/main-project/A_auto_mall.py", line 55
    col1:
         ^
SyntaxError: invalid syntax

ERROR:root:[auto_mall] 오류: Traceback (most recent call last):
  File "/Users/choenamho/Documents/GitHub/main-project/Home.py", line 67, in <module>
    import A_auto_mall as auto
  File "/Users/choenamho/Documents/GitHub/main-project/A_auto_mall.py", line 55
    wcol1:
          ^
SyntaxError: invalid syntax

ERROR:root:[auto_mall] 오류: Traceback (most recent call last):
  File "/Users/choenamho/Documents/GitHub/main-project/Home.py", line 68, in <module>
    auto.app()
  File "/Users/choenamho/Documents/GitHub/main-project/A_auto_mall.py", line 125, in app
    cols = st.columns(3)
  File "/Users/choenamho/hi/lib/python3.10/site-packages/streamlit/runtime/metrics_util.py", line 410, in wrapped_func
    result = non_optional_func(*args, **kwargs)
  File "/Users/choenamho/hi/lib/python3.10/site-packages/streamlit/elements/layouts.py", line 383, in columns
    return [row._block(column_proto(w / total_weight)) for w in weights]
  File "/Users/choenamho/hi/lib/python3.10/site-packages/streamlit/elements/layouts.py", line 383, in <listcomp>
    return [row._block(column_proto(w / total_weight)) for w in weights]
  File "/Users/choenamho/hi/lib/python3.10/site-packages/streamlit/delta_generator.py", line 518, in _block
    _check_nested_element_violation(self, block_type, ancestor_block_types)
  File "/Users/choenamho/hi/lib/python3.10/site-packages/streamlit/delta_generator.py", line 590, in _check_nested_element_violation
    raise StreamlitAPIException(
streamlit.errors.StreamlitAPIException: Columns can only be placed inside other columns up to one level of nesting.

ERROR:root:[auto_mall] 오류: Traceback (most recent call last):
  File "/Users/choenamho/Documents/GitHub/main-project/Home.py", line 68, in <module>
    auto.app()
  File "/Users/choenamho/Documents/GitHub/main-project/A_auto_mall.py", line 55, in app
    with col1:
UnboundLocalError: local variable 'col1' referenced before assignment

ERROR:root:[auto_mall] 오류: Traceback (most recent call last):
  File "/Users/choenamho/Documents/GitHub/main-project/Home.py", line 68, in <module>
    auto.app()
  File "/Users/choenamho/Documents/GitHub/main-project/A_auto_mall.py", line 55, in app
    with col1:
UnboundLocalError: local variable 'col1' referenced before assignment

ERROR:root:[auto_mall] 오류: Traceback (most recent call last):
  File "/Users/choenamho/Documents/GitHub/main-project/Home.py", line 68, in <module>
    auto.app()
  File "/Users/choenamho/Documents/GitHub/main-project/A_auto_mall.py", line 55, in app
    with col1:
UnboundLocalError: local variable 'col1' referenced before assignment

ERROR:root:[auto_mall] 오류: Traceback (most recent call last):
  File "/Users/choenamho/Documents/GitHub/main-project/Home.py", line 68, in <module>
    auto.app()
  File "/Users/choenamho/Documents/GitHub/main-project/A_auto_mall.py", line 55, in app
    with col1:
UnboundLocalError: local variable 'col1' referenced before assignment

ERROR:root:[auto_mall] 오류: Traceback (most recent call last):
  File "/Users/choenamho/Documents/GitHub/main-project/Home.py", line 68, in <module>
    auto.app()
  File "/Users/choenamho/Documents/GitHub/main-project/A_auto_mall.py", line 55, in app
    with col1:
UnboundLocalError: local variable 'col1' referenced before assignment

ERROR:root:[auto_mall] 오류: Traceback (most recent call last):
  File "/Users/choenamho/Documents/GitHub/main-project/Home.py", line 68, in <module>
    auto.app()
  File "/Users/choenamho/Documents/GitHub/main-project/A_auto_mall.py", line 55, in app
    with col1:
UnboundLocalError: local variable 'col1' referenced before assignment

ERROR:root:[auto_mall] 오류: Traceback (most recent call last):
  File "/Users/choenamho/Documents/GitHub/main-project/Home.py", line 68, in <module>
    auto.app()
  File "/Users/choenamho/Documents/GitHub/main-project/A_auto_mall.py", line 55, in app
    with col1:
UnboundLocalError: local variable 'col1' referenced before assignment

ERROR:root:[auto_mall] 오류: Traceback (most recent call last):
  File "/Users/choenamho/Documents/GitHub/main-project/Home.py", line 68, in <module>
    auto.app()
  File "/Users/choenamho/Documents/GitHub/main-project/A_auto_mall.py", line 55, in app
    with col1:
UnboundLocalError: local variable 'col1' referenced before assignment

ERROR:root:[auto_mall] 오류: Traceback (most recent call last):
  File "/Users/choenamho/Documents/GitHub/main-project/Home.py", line 68, in <module>
    auto.app()
  File "/Users/choenamho/Documents/GitHub/main-project/A_auto_mall.py", line 55, in app
    with col1:
UnboundLocalError: local variable 'col1' referenced before assignment

ERROR:root:[auto_mall] 오류: Traceback (most recent call last):
  File "/Users/choenamho/Documents/GitHub/main-project/Home.py", line 68, in <module>
    auto.app()
  File "/Users/choenamho/Documents/GitHub/main-project/A_auto_mall.py", line 125, in app
    cols = st.columns(3)
  File "/Users/choenamho/hi/lib/python3.10/site-packages/streamlit/runtime/metrics_util.py", line 410, in wrapped_func
    result = non_optional_func(*args, **kwargs)
  File "/Users/choenamho/hi/lib/python3.10/site-packages/streamlit/elements/layouts.py", line 383, in columns
    return [row._block(column_proto(w / total_weight)) for w in weights]
  File "/Users/choenamho/hi/lib/python3.10/site-packages/streamlit/elements/layouts.py", line 383, in <listcomp>
    return [row._block(column_proto(w / total_weight)) for w in weights]
  File "/Users/choenamho/hi/lib/python3.10/site-packages/streamlit/delta_generator.py", line 518, in _block
    _check_nested_element_violation(self, block_type, ancestor_block_types)
  File "/Users/choenamho/hi/lib/python3.10/site-packages/streamlit/delta_generator.py", line 590, in _check_nested_element_violation
    raise StreamlitAPIException(
streamlit.errors.StreamlitAPIException: Columns can only be placed inside other columns up to one level of nesting.

ERROR:root:[auto_mall] 오류: Traceback (most recent call last):
  File "/Users/choenamho/Documents/GitHub/main-project/Home.py", line 67, in <module>
    import A_auto_mall as auto
  File "/Users/choenamho/Documents/GitHub/main-project/A_auto_mall.py", line 186
    with col_Auro_mall_1:
                         ^
IndentationError: expected an indented block after 'with' statement on line 186

ERROR:root:[auto_mall] 오류: Traceback (most recent call last):
  File "/Users/choenamho/Documents/GitHub/main-project/Home.py", line 67, in <module>
    import A_auto_mall as auto
  File "/Users/choenamho/Documents/GitHub/main-project/A_auto_mall.py", line 186
    with col_Auro_mall_2:
                         ^
IndentationError: expected an indented block after 'with' statement on line 186

ERROR:root:[auto_mall] 오류: Traceback (most recent call last):
  File "/Users/choenamho/Documents/GitHub/main-project/Home.py", line 67, in <module>
    import A_auto_mall as auto
  File "/Users/choenamho/Documents/GitHub/main-project/A_auto_mall.py", line 168
    with col_Auro_mall_2:
                         ^
IndentationError: expected an indented block after 'with' statement on line 168

ERROR:root:[auto_mall] 오류: Traceback (most recent call last):
  File "/Users/choenamho/Documents/GitHub/main-project/Home.py", line 67, in <module>
    import A_auto_mall as auto
  File "/Users/choenamho/Documents/GitHub/main-project/A_auto_mall.py", line 171
    이름 = st.text_input("이름")
IndentationError: unexpected indent

ERROR:root:[auto_mall] 오류: Traceback (most recent call last):
  File "/Users/choenamho/Documents/GitHub/main-project/Home.py", line 67, in <module>
    import A_auto_mall as auto
  File "/Users/choenamho/Documents/GitHub/main-project/A_auto_mall.py", line 171
    이름 = st.text_input("이름")
IndentationError: unexpected indent

ERROR:root:[auto_mall] 오류: Traceback (most recent call last):
  File "/Users/choenamho/Documents/GitHub/main-project/Home.py", line 68, in <module>
    auto.app()
  File "/Users/choenamho/Documents/GitHub/main-project/A_auto_mall.py", line 125, in app
    cols = st.columns(3)
  File "/Users/choenamho/hi/lib/python3.10/site-packages/streamlit/runtime/metrics_util.py", line 410, in wrapped_func
    result = non_optional_func(*args, **kwargs)
  File "/Users/choenamho/hi/lib/python3.10/site-packages/streamlit/elements/layouts.py", line 383, in columns
    return [row._block(column_proto(w / total_weight)) for w in weights]
  File "/Users/choenamho/hi/lib/python3.10/site-packages/streamlit/elements/layouts.py", line 383, in <listcomp>
    return [row._block(column_proto(w / total_weight)) for w in weights]
  File "/Users/choenamho/hi/lib/python3.10/site-packages/streamlit/delta_generator.py", line 518, in _block
    _check_nested_element_violation(self, block_type, ancestor_block_types)
  File "/Users/choenamho/hi/lib/python3.10/site-packages/streamlit/delta_generator.py", line 590, in _check_nested_element_violation
    raise StreamlitAPIException(
streamlit.errors.StreamlitAPIException: Columns can only be placed inside other columns up to one level of nesting.

ERROR:root:[auto_mall] 오류: Traceback (most recent call last):
  File "/Users/choenamho/Documents/GitHub/main-project/Home.py", line 68, in <module>
    auto.app()
  File "/Users/choenamho/Documents/GitHub/main-project/A_auto_mall.py", line 125, in app
    cols = st.columns(3)
  File "/Users/choenamho/hi/lib/python3.10/site-packages/streamlit/runtime/metrics_util.py", line 410, in wrapped_func
    result = non_optional_func(*args, **kwargs)
  File "/Users/choenamho/hi/lib/python3.10/site-packages/streamlit/elements/layouts.py", line 383, in columns
    return [row._block(column_proto(w / total_weight)) for w in weights]
  File "/Users/choenamho/hi/lib/python3.10/site-packages/streamlit/elements/layouts.py", line 383, in <listcomp>
    return [row._block(column_proto(w / total_weight)) for w in weights]
  File "/Users/choenamho/hi/lib/python3.10/site-packages/streamlit/delta_generator.py", line 518, in _block
    _check_nested_element_violation(self, block_type, ancestor_block_types)
  File "/Users/choenamho/hi/lib/python3.10/site-packages/streamlit/delta_generator.py", line 590, in _check_nested_element_violation
    raise StreamlitAPIException(
streamlit.errors.StreamlitAPIException: Columns can only be placed inside other columns up to one level of nesting.

ERROR:root:[auto_mall] 오류: Traceback (most recent call last):
  File "/Users/choenamho/Documents/GitHub/main-project/Home.py", line 67, in <module>
    import A_auto_mall as auto
  File "/Users/choenamho/Documents/GitHub/main-project/A_auto_mall.py", line 173
    이름 = st.text_input("이름")
IndentationError: unexpected indent

ERROR:root:[auto_mall] 오류: Traceback (most recent call last):
  File "/Users/choenamho/Documents/GitHub/main-project/Home.py", line 68, in <module>
    auto.app()
  File "/Users/choenamho/Documents/GitHub/main-project/A_auto_mall.py", line 125, in app
    cols = st.columns(3)
  File "/Users/choenamho/hi/lib/python3.10/site-packages/streamlit/runtime/metrics_util.py", line 410, in wrapped_func
    result = non_optional_func(*args, **kwargs)
  File "/Users/choenamho/hi/lib/python3.10/site-packages/streamlit/elements/layouts.py", line 383, in columns
    return [row._block(column_proto(w / total_weight)) for w in weights]
  File "/Users/choenamho/hi/lib/python3.10/site-packages/streamlit/elements/layouts.py", line 383, in <listcomp>
    return [row._block(column_proto(w / total_weight)) for w in weights]
  File "/Users/choenamho/hi/lib/python3.10/site-packages/streamlit/delta_generator.py", line 518, in _block
    _check_nested_element_violation(self, block_type, ancestor_block_types)
  File "/Users/choenamho/hi/lib/python3.10/site-packages/streamlit/delta_generator.py", line 590, in _check_nested_element_violation
    raise StreamlitAPIException(
streamlit.errors.StreamlitAPIException: Columns can only be placed inside other columns up to one level of nesting.

ERROR:root:[auto_mall] 오류: Traceback (most recent call last):
  File "/Users/choenamho/Documents/GitHub/main-project/Home.py", line 68, in <module>
    auto.app()
  File "/Users/choenamho/Documents/GitHub/main-project/A_auto_mall.py", line 126, in app
    cols = st.columns(3)
  File "/Users/choenamho/hi/lib/python3.10/site-packages/streamlit/runtime/metrics_util.py", line 410, in wrapped_func
    result = non_optional_func(*args, **kwargs)
  File "/Users/choenamho/hi/lib/python3.10/site-packages/streamlit/elements/layouts.py", line 383, in columns
    return [row._block(column_proto(w / total_weight)) for w in weights]
  File "/Users/choenamho/hi/lib/python3.10/site-packages/streamlit/elements/layouts.py", line 383, in <listcomp>
    return [row._block(column_proto(w / total_weight)) for w in weights]
  File "/Users/choenamho/hi/lib/python3.10/site-packages/streamlit/delta_generator.py", line 518, in _block
    _check_nested_element_violation(self, block_type, ancestor_block_types)
  File "/Users/choenamho/hi/lib/python3.10/site-packages/streamlit/delta_generator.py", line 590, in _check_nested_element_violation
    raise StreamlitAPIException(
streamlit.errors.StreamlitAPIException: Columns can only be placed inside other columns up to one level of nesting.

ERROR:root:[auto_mall] 오류: Traceback (most recent call last):
  File "/Users/choenamho/Documents/GitHub/main-project/Home.py", line 68, in <module>
    auto.app()
  File "/Users/choenamho/Documents/GitHub/main-project/A_auto_mall.py", line 123, in app
    cols = st.columns(3)
  File "/Users/choenamho/hi/lib/python3.10/site-packages/streamlit/runtime/metrics_util.py", line 410, in wrapped_func
    result = non_optional_func(*args, **kwargs)
  File "/Users/choenamho/hi/lib/python3.10/site-packages/streamlit/elements/layouts.py", line 383, in columns
    return [row._block(column_proto(w / total_weight)) for w in weights]
  File "/Users/choenamho/hi/lib/python3.10/site-packages/streamlit/elements/layouts.py", line 383, in <listcomp>
    return [row._block(column_proto(w / total_weight)) for w in weights]
  File "/Users/choenamho/hi/lib/python3.10/site-packages/streamlit/delta_generator.py", line 518, in _block
    _check_nested_element_violation(self, block_type, ancestor_block_types)
  File "/Users/choenamho/hi/lib/python3.10/site-packages/streamlit/delta_generator.py", line 590, in _check_nested_element_violation
    raise StreamlitAPIException(
streamlit.errors.StreamlitAPIException: Columns can only be placed inside other columns up to one level of nesting.

ERROR:root:[auto_mall] 오류: Traceback (most recent call last):
  File "/Users/choenamho/Documents/GitHub/main-project/Home.py", line 67, in <module>
    import A_auto_mall as auto
  File "/Users/choenamho/Documents/GitHub/main-project/A_auto_mall.py", line 171
    st.session_state.current_page = "home"
                                          ^
IndentationError: unindent does not match any outer indentation level

ERROR:root:[auto_mall] 오류: Traceback (most recent call last):
  File "/Users/choenamho/Documents/GitHub/main-project/Home.py", line 67, in <module>
    import A_auto_mall as auto
  File "/Users/choenamho/Documents/GitHub/main-project/A_auto_mall.py", line 171
    st.session_state.current_page = "home"
                                          ^
IndentationError: unindent does not match any outer indentation level

ERROR:root:[auto_mall] 오류: Traceback (most recent call last):
  File "/Users/choenamho/Documents/GitHub/main-project/Home.py", line 67, in <module>
    import A_auto_mall as auto
  File "/Users/choenamho/Documents/GitHub/main-project/A_auto_mall.py", line 171
    st.session_state.current_page = "home"
    ^^
IndentationError: expected an indented block after 'if' statement on line 170

ERROR:root:[auto_mall] 오류: Traceback (most recent call last):
  File "/Users/choenamho/Documents/GitHub/main-project/Home.py", line 68, in <module>
    auto.app()
  File "/Users/choenamho/Documents/GitHub/main-project/A_auto_mall.py", line 123, in app
    cols = st.columns(3)
  File "/Users/choenamho/hi/lib/python3.10/site-packages/streamlit/runtime/metrics_util.py", line 410, in wrapped_func
    result = non_optional_func(*args, **kwargs)
  File "/Users/choenamho/hi/lib/python3.10/site-packages/streamlit/elements/layouts.py", line 383, in columns
    return [row._block(column_proto(w / total_weight)) for w in weights]
  File "/Users/choenamho/hi/lib/python3.10/site-packages/streamlit/elements/layouts.py", line 383, in <listcomp>
    return [row._block(column_proto(w / total_weight)) for w in weights]
  File "/Users/choenamho/hi/lib/python3.10/site-packages/streamlit/delta_generator.py", line 518, in _block
    _check_nested_element_violation(self, block_type, ancestor_block_types)
  File "/Users/choenamho/hi/lib/python3.10/site-packages/streamlit/delta_generator.py", line 590, in _check_nested_element_violation
    raise StreamlitAPIException(
streamlit.errors.StreamlitAPIException: Columns can only be placed inside other columns up to one level of nesting.

ERROR:root:[auto_mall] 오류: Traceback (most recent call last):
  File "/Users/choenamho/Documents/GitHub/main-project/Home.py", line 68, in <module>
    auto.app()
  File "/Users/choenamho/Documents/GitHub/main-project/A_auto_mall.py", line 123, in app
    cols = st.columns(3)
  File "/Users/choenamho/hi/lib/python3.10/site-packages/streamlit/runtime/metrics_util.py", line 410, in wrapped_func
    result = non_optional_func(*args, **kwargs)
  File "/Users/choenamho/hi/lib/python3.10/site-packages/streamlit/elements/layouts.py", line 383, in columns
    return [row._block(column_proto(w / total_weight)) for w in weights]
  File "/Users/choenamho/hi/lib/python3.10/site-packages/streamlit/elements/layouts.py", line 383, in <listcomp>
    return [row._block(column_proto(w / total_weight)) for w in weights]
  File "/Users/choenamho/hi/lib/python3.10/site-packages/streamlit/delta_generator.py", line 518, in _block
    _check_nested_element_violation(self, block_type, ancestor_block_types)
  File "/Users/choenamho/hi/lib/python3.10/site-packages/streamlit/delta_generator.py", line 590, in _check_nested_element_violation
    raise StreamlitAPIException(
streamlit.errors.StreamlitAPIException: Columns can only be placed inside other columns up to one level of nesting.

ERROR:root:[auto_mall] 오류: Traceback (most recent call last):
  File "/Users/choenamho/Documents/GitHub/main-project/Home.py", line 68, in <module>
    auto.app()
  File "/Users/choenamho/Documents/GitHub/main-project/A_auto_mall.py", line 122, in app
    cols = st.columns(3)
  File "/Users/choenamho/hi/lib/python3.10/site-packages/streamlit/runtime/metrics_util.py", line 410, in wrapped_func
    result = non_optional_func(*args, **kwargs)
  File "/Users/choenamho/hi/lib/python3.10/site-packages/streamlit/elements/layouts.py", line 383, in columns
    return [row._block(column_proto(w / total_weight)) for w in weights]
  File "/Users/choenamho/hi/lib/python3.10/site-packages/streamlit/elements/layouts.py", line 383, in <listcomp>
    return [row._block(column_proto(w / total_weight)) for w in weights]
  File "/Users/choenamho/hi/lib/python3.10/site-packages/streamlit/delta_generator.py", line 518, in _block
    _check_nested_element_violation(self, block_type, ancestor_block_types)
  File "/Users/choenamho/hi/lib/python3.10/site-packages/streamlit/delta_generator.py", line 590, in _check_nested_element_violation
    raise StreamlitAPIException(
streamlit.errors.StreamlitAPIException: Columns can only be placed inside other columns up to one level of nesting.

ERROR:root:[auto_mall] 오류: Traceback (most recent call last):
  File "/Users/choenamho/Documents/GitHub/main-project/Home.py", line 68, in <module>
    auto.app()
  File "/Users/choenamho/Documents/GitHub/main-project/A_auto_mall.py", line 121, in app
    cols = st.columns(3)
  File "/Users/choenamho/hi/lib/python3.10/site-packages/streamlit/runtime/metrics_util.py", line 410, in wrapped_func
    result = non_optional_func(*args, **kwargs)
  File "/Users/choenamho/hi/lib/python3.10/site-packages/streamlit/elements/layouts.py", line 383, in columns
    return [row._block(column_proto(w / total_weight)) for w in weights]
  File "/Users/choenamho/hi/lib/python3.10/site-packages/streamlit/elements/layouts.py", line 383, in <listcomp>
    return [row._block(column_proto(w / total_weight)) for w in weights]
  File "/Users/choenamho/hi/lib/python3.10/site-packages/streamlit/delta_generator.py", line 518, in _block
    _check_nested_element_violation(self, block_type, ancestor_block_types)
  File "/Users/choenamho/hi/lib/python3.10/site-packages/streamlit/delta_generator.py", line 590, in _check_nested_element_violation
    raise StreamlitAPIException(
streamlit.errors.StreamlitAPIException: Columns can only be placed inside other columns up to one level of nesting.

ERROR:root:[auto_mall] 오류: Traceback (most recent call last):
  File "/Users/choenamho/Documents/GitHub/main-project/Home.py", line 68, in <module>
    auto.app()
  File "/Users/choenamho/Documents/GitHub/main-project/A_auto_mall.py", line 136, in app
    display_car_section(casper, "캐스퍼", "선택")
  File "/Users/choenamho/Documents/GitHub/main-project/A_auto_mall.py", line 56, in display_car_section
    cols = st.columns(3)
  File "/Users/choenamho/hi/lib/python3.10/site-packages/streamlit/runtime/metrics_util.py", line 410, in wrapped_func
    result = non_optional_func(*args, **kwargs)
  File "/Users/choenamho/hi/lib/python3.10/site-packages/streamlit/elements/layouts.py", line 383, in columns
    return [row._block(column_proto(w / total_weight)) for w in weights]
  File "/Users/choenamho/hi/lib/python3.10/site-packages/streamlit/elements/layouts.py", line 383, in <listcomp>
    return [row._block(column_proto(w / total_weight)) for w in weights]
  File "/Users/choenamho/hi/lib/python3.10/site-packages/streamlit/delta_generator.py", line 518, in _block
    _check_nested_element_violation(self, block_type, ancestor_block_types)
  File "/Users/choenamho/hi/lib/python3.10/site-packages/streamlit/delta_generator.py", line 590, in _check_nested_element_violation
    raise StreamlitAPIException(
streamlit.errors.StreamlitAPIException: Columns can only be placed inside other columns up to one level of nesting.

ERROR:root:[auto_mall] 오류: Traceback (most recent call last):
  File "/Users/choenamho/Documents/GitHub/main-project/Home.py", line 68, in <module>
    auto.app()
  File "/Users/choenamho/Documents/GitHub/main-project/A_auto_mall.py", line 136, in app
    display_car_section(casper, "캐스퍼", "선택")
  File "/Users/choenamho/Documents/GitHub/main-project/A_auto_mall.py", line 56, in display_car_section
    cols = st.columns(3)
  File "/Users/choenamho/hi/lib/python3.10/site-packages/streamlit/runtime/metrics_util.py", line 410, in wrapped_func
    result = non_optional_func(*args, **kwargs)
  File "/Users/choenamho/hi/lib/python3.10/site-packages/streamlit/elements/layouts.py", line 383, in columns
    return [row._block(column_proto(w / total_weight)) for w in weights]
  File "/Users/choenamho/hi/lib/python3.10/site-packages/streamlit/elements/layouts.py", line 383, in <listcomp>
    return [row._block(column_proto(w / total_weight)) for w in weights]
  File "/Users/choenamho/hi/lib/python3.10/site-packages/streamlit/delta_generator.py", line 518, in _block
    _check_nested_element_violation(self, block_type, ancestor_block_types)
  File "/Users/choenamho/hi/lib/python3.10/site-packages/streamlit/delta_generator.py", line 590, in _check_nested_element_violation
    raise StreamlitAPIException(
streamlit.errors.StreamlitAPIException: Columns can only be placed inside other columns up to one level of nesting.

ERROR:root:[auto_mall] 오류: Traceback (most recent call last):
  File "/Users/choenamho/Documents/GitHub/main-project/Home.py", line 68, in <module>
    auto.app()
  File "/Users/choenamho/Documents/GitHub/main-project/A_auto_mall.py", line 136, in app
    display_car_section(casper, "캐스퍼", "선택")
  File "/Users/choenamho/Documents/GitHub/main-project/A_auto_mall.py", line 56, in display_car_section
    cols = st.columns(3)
  File "/Users/choenamho/hi/lib/python3.10/site-packages/streamlit/runtime/metrics_util.py", line 410, in wrapped_func
    result = non_optional_func(*args, **kwargs)
  File "/Users/choenamho/hi/lib/python3.10/site-packages/streamlit/elements/layouts.py", line 383, in columns
    return [row._block(column_proto(w / total_weight)) for w in weights]
  File "/Users/choenamho/hi/lib/python3.10/site-packages/streamlit/elements/layouts.py", line 383, in <listcomp>
    return [row._block(column_proto(w / total_weight)) for w in weights]
  File "/Users/choenamho/hi/lib/python3.10/site-packages/streamlit/delta_generator.py", line 518, in _block
    _check_nested_element_violation(self, block_type, ancestor_block_types)
  File "/Users/choenamho/hi/lib/python3.10/site-packages/streamlit/delta_generator.py", line 590, in _check_nested_element_violation
    raise StreamlitAPIException(
streamlit.errors.StreamlitAPIException: Columns can only be placed inside other columns up to one level of nesting.

ERROR:root:[auto_mall] 오류: Traceback (most recent call last):
  File "/Users/choenamho/Documents/GitHub/main-project/Home.py", line 68, in <module>
    auto.app()
  File "/Users/choenamho/Documents/GitHub/main-project/A_auto_mall.py", line 121, in app
    cols = st.columns(3)
  File "/Users/choenamho/hi/lib/python3.10/site-packages/streamlit/runtime/metrics_util.py", line 410, in wrapped_func
    result = non_optional_func(*args, **kwargs)
  File "/Users/choenamho/hi/lib/python3.10/site-packages/streamlit/elements/layouts.py", line 383, in columns
    return [row._block(column_proto(w / total_weight)) for w in weights]
  File "/Users/choenamho/hi/lib/python3.10/site-packages/streamlit/elements/layouts.py", line 383, in <listcomp>
    return [row._block(column_proto(w / total_weight)) for w in weights]
  File "/Users/choenamho/hi/lib/python3.10/site-packages/streamlit/delta_generator.py", line 518, in _block
    _check_nested_element_violation(self, block_type, ancestor_block_types)
  File "/Users/choenamho/hi/lib/python3.10/site-packages/streamlit/delta_generator.py", line 590, in _check_nested_element_violation
    raise StreamlitAPIException(
streamlit.errors.StreamlitAPIException: Columns can only be placed inside other columns up to one level of nesting.

ERROR:root:[auto_mall] 오류: Traceback (most recent call last):
  File "/Users/choenamho/Documents/GitHub/main-project/Home.py", line 68, in <module>
    auto.app()
  File "/Users/choenamho/Documents/GitHub/main-project/A_auto_mall.py", line 145, in app
    st.experimental_rerun()
AttributeError: module 'streamlit' has no attribute 'experimental_rerun'

ERROR:root:[auto_mall] 오류: Traceback (most recent call last):
  File "/Users/choenamho/Documents/GitHub/main-project/Home.py", line 68, in <module>
    auto.app()
  File "/Users/choenamho/Documents/GitHub/main-project/A_auto_mall.py", line 145, in app
    st.experimental_rerun()
AttributeError: module 'streamlit' has no attribute 'experimental_rerun'

ERROR:root:[auto_mall] 오류: Traceback (most recent call last):
  File "/Users/choenamho/Documents/GitHub/main-project/Home.py", line 68, in <module>
    auto.app()
  File "/Users/choenamho/Documents/GitHub/main-project/A_auto_mall.py", line 121, in app
    cols = st.columns(3)
  File "/Users/choenamho/hi/lib/python3.10/site-packages/streamlit/runtime/metrics_util.py", line 410, in wrapped_func
    result = non_optional_func(*args, **kwargs)
  File "/Users/choenamho/hi/lib/python3.10/site-packages/streamlit/elements/layouts.py", line 383, in columns
    return [row._block(column_proto(w / total_weight)) for w in weights]
  File "/Users/choenamho/hi/lib/python3.10/site-packages/streamlit/elements/layouts.py", line 383, in <listcomp>
    return [row._block(column_proto(w / total_weight)) for w in weights]
  File "/Users/choenamho/hi/lib/python3.10/site-packages/streamlit/delta_generator.py", line 518, in _block
    _check_nested_element_violation(self, block_type, ancestor_block_types)
  File "/Users/choenamho/hi/lib/python3.10/site-packages/streamlit/delta_generator.py", line 590, in _check_nested_element_violation
    raise StreamlitAPIException(
streamlit.errors.StreamlitAPIException: Columns can only be placed inside other columns up to one level of nesting.

ERROR:root:[auto_mall] 오류: Traceback (most recent call last):
  File "/Users/choenamho/Documents/GitHub/main-project/Home.py", line 68, in <module>
    auto.app()
  File "/Users/choenamho/Documents/GitHub/main-project/A_auto_mall.py", line 121, in app
    cols = st.columns(3)
  File "/Users/choenamho/hi/lib/python3.10/site-packages/streamlit/runtime/metrics_util.py", line 410, in wrapped_func
    result = non_optional_func(*args, **kwargs)
  File "/Users/choenamho/hi/lib/python3.10/site-packages/streamlit/elements/layouts.py", line 383, in columns
    return [row._block(column_proto(w / total_weight)) for w in weights]
  File "/Users/choenamho/hi/lib/python3.10/site-packages/streamlit/elements/layouts.py", line 383, in <listcomp>
    return [row._block(column_proto(w / total_weight)) for w in weights]
  File "/Users/choenamho/hi/lib/python3.10/site-packages/streamlit/delta_generator.py", line 518, in _block
    _check_nested_element_violation(self, block_type, ancestor_block_types)
  File "/Users/choenamho/hi/lib/python3.10/site-packages/streamlit/delta_generator.py", line 590, in _check_nested_element_violation
    raise StreamlitAPIException(
streamlit.errors.StreamlitAPIException: Columns can only be placed inside other columns up to one level of nesting.

ERROR:root:[auto_mall] 오류: Traceback (most recent call last):
  File "/Users/choenamho/Documents/GitHub/main-project/Home.py", line 67, in <module>
    import A_auto_mall as auto
  File "/Users/choenamho/Documents/GitHub/main-project/A_auto_mall.py", line 161
    관심차종 = st.multiselect("관심 차종", ["캐스퍼", "캐스퍼 일렉트
                                           ^
SyntaxError: unterminated string literal (detected at line 161)

ERROR:root:[auto_mall] 오류: Traceback (most recent call last):
  File "/Users/choenamho/Documents/GitHub/main-project/Home.py", line 68, in <module>
    auto.app()
  File "/Users/choenamho/Documents/GitHub/main-project/A_auto_mall.py", line 121, in app
    cols = st.columns(3)
  File "/Users/choenamho/hi/lib/python3.10/site-packages/streamlit/runtime/metrics_util.py", line 410, in wrapped_func
    result = non_optional_func(*args, **kwargs)
  File "/Users/choenamho/hi/lib/python3.10/site-packages/streamlit/elements/layouts.py", line 383, in columns
    return [row._block(column_proto(w / total_weight)) for w in weights]
  File "/Users/choenamho/hi/lib/python3.10/site-packages/streamlit/elements/layouts.py", line 383, in <listcomp>
    return [row._block(column_proto(w / total_weight)) for w in weights]
  File "/Users/choenamho/hi/lib/python3.10/site-packages/streamlit/delta_generator.py", line 518, in _block
    _check_nested_element_violation(self, block_type, ancestor_block_types)
  File "/Users/choenamho/hi/lib/python3.10/site-packages/streamlit/delta_generator.py", line 590, in _check_nested_element_violation
    raise StreamlitAPIException(
streamlit.errors.StreamlitAPIException: Columns can only be placed inside other columns up to one level of nesting.

ERROR:root:[auto_mall] 오류: Traceback (most recent call last):
  File "/Users/choenamho/Documents/GitHub/main-project/Home.py", line 67, in <module>
    import A_auto_mall as auto
  File "/Users/choenamho/Documents/GitHub/main-project/A_auto_mall.py", line 49
    else:
    ^^^^
SyntaxError: invalid syntax

ERROR:root:[auto_mall] 오류: Traceback (most recent call last):
  File "/Users/choenamho/Documents/GitHub/main-project/Home.py", line 68, in <module>
    auto.app()
  File "/Users/choenamho/Documents/GitHub/main-project/A_auto_mall.py", line 126, in app
    st.experimental_rerun()
AttributeError: module 'streamlit' has no attribute 'experimental_rerun'

ERROR:root:[auto_mall] 오류: Traceback (most recent call last):
  File "/Users/choenamho/Documents/GitHub/main-project/Home.py", line 68, in <module>
    auto.app()
  File "/Users/choenamho/Documents/GitHub/main-project/A_auto_mall.py", line 121, in app
    cols = st.columns(3)
  File "/Users/choenamho/hi/lib/python3.10/site-packages/streamlit/runtime/metrics_util.py", line 410, in wrapped_func
    result = non_optional_func(*args, **kwargs)
  File "/Users/choenamho/hi/lib/python3.10/site-packages/streamlit/elements/layouts.py", line 383, in columns
    return [row._block(column_proto(w / total_weight)) for w in weights]
  File "/Users/choenamho/hi/lib/python3.10/site-packages/streamlit/elements/layouts.py", line 383, in <listcomp>
    return [row._block(column_proto(w / total_weight)) for w in weights]
  File "/Users/choenamho/hi/lib/python3.10/site-packages/streamlit/delta_generator.py", line 518, in _block
    _check_nested_element_violation(self, block_type, ancestor_block_types)
  File "/Users/choenamho/hi/lib/python3.10/site-packages/streamlit/delta_generator.py", line 590, in _check_nested_element_violation
    raise StreamlitAPIException(
streamlit.errors.StreamlitAPIException: Columns can only be placed inside other columns up to one level of nesting.

ERROR:root:[auto_mall] 오류: Traceback (most recent call last):
  File "/Users/choenamho/Documents/GitHub/main-project/Home.py", line 68, in <module>
    auto.app()
  File "/Users/choenamho/Documents/GitHub/main-project/A_auto_mall.py", line 121, in app
    cols = st.columns(3)
  File "/Users/choenamho/hi/lib/python3.10/site-packages/streamlit/runtime/metrics_util.py", line 410, in wrapped_func
    result = non_optional_func(*args, **kwargs)
  File "/Users/choenamho/hi/lib/python3.10/site-packages/streamlit/elements/layouts.py", line 383, in columns
    return [row._block(column_proto(w / total_weight)) for w in weights]
  File "/Users/choenamho/hi/lib/python3.10/site-packages/streamlit/elements/layouts.py", line 383, in <listcomp>
    return [row._block(column_proto(w / total_weight)) for w in weights]
  File "/Users/choenamho/hi/lib/python3.10/site-packages/streamlit/delta_generator.py", line 518, in _block
    _check_nested_element_violation(self, block_type, ancestor_block_types)
  File "/Users/choenamho/hi/lib/python3.10/site-packages/streamlit/delta_generator.py", line 590, in _check_nested_element_violation
    raise StreamlitAPIException(
streamlit.errors.StreamlitAPIException: Columns can only be placed inside other columns up to one level of nesting.

ERROR:root:[auto_mall] 오류: Traceback (most recent call last):
  File "/Users/choenamho/Documents/GitHub/main-project/Home.py", line 68, in <module>
    auto.app()
  File "/Users/choenamho/Documents/GitHub/main-project/A_auto_mall.py", line 122, in app
    cols = st.columns(3)
  File "/Users/choenamho/hi/lib/python3.10/site-packages/streamlit/runtime/metrics_util.py", line 410, in wrapped_func
    result = non_optional_func(*args, **kwargs)
  File "/Users/choenamho/hi/lib/python3.10/site-packages/streamlit/elements/layouts.py", line 383, in columns
    return [row._block(column_proto(w / total_weight)) for w in weights]
  File "/Users/choenamho/hi/lib/python3.10/site-packages/streamlit/elements/layouts.py", line 383, in <listcomp>
    return [row._block(column_proto(w / total_weight)) for w in weights]
  File "/Users/choenamho/hi/lib/python3.10/site-packages/streamlit/delta_generator.py", line 518, in _block
    _check_nested_element_violation(self, block_type, ancestor_block_types)
  File "/Users/choenamho/hi/lib/python3.10/site-packages/streamlit/delta_generator.py", line 590, in _check_nested_element_violation
    raise StreamlitAPIException(
streamlit.errors.StreamlitAPIException: Columns can only be placed inside other columns up to one level of nesting.

ERROR:root:[auto_mall] 오류: Traceback (most recent call last):
  File "/Users/choenamho/Documents/GitHub/main-project/Home.py", line 68, in <module>
    auto.app()
  File "/Users/choenamho/Documents/GitHub/main-project/A_auto_mall.py", line 123, in app
    cols = st.columns(3)
  File "/Users/choenamho/hi/lib/python3.10/site-packages/streamlit/runtime/metrics_util.py", line 410, in wrapped_func
    result = non_optional_func(*args, **kwargs)
  File "/Users/choenamho/hi/lib/python3.10/site-packages/streamlit/elements/layouts.py", line 383, in columns
    return [row._block(column_proto(w / total_weight)) for w in weights]
  File "/Users/choenamho/hi/lib/python3.10/site-packages/streamlit/elements/layouts.py", line 383, in <listcomp>
    return [row._block(column_proto(w / total_weight)) for w in weights]
  File "/Users/choenamho/hi/lib/python3.10/site-packages/streamlit/delta_generator.py", line 518, in _block
    _check_nested_element_violation(self, block_type, ancestor_block_types)
  File "/Users/choenamho/hi/lib/python3.10/site-packages/streamlit/delta_generator.py", line 590, in _check_nested_element_violation
    raise StreamlitAPIException(
streamlit.errors.StreamlitAPIException: Columns can only be placed inside other columns up to one level of nesting.

ERROR:root:[auto_mall] 오류: Traceback (most recent call last):
  File "/Users/choenamho/Documents/GitHub/main-project/Home.py", line 68, in <module>
    auto.app()
  File "/Users/choenamho/Documents/GitHub/main-project/A_auto_mall.py", line 123, in app
    cols = st.columns(3)
  File "/Users/choenamho/hi/lib/python3.10/site-packages/streamlit/runtime/metrics_util.py", line 410, in wrapped_func
    result = non_optional_func(*args, **kwargs)
  File "/Users/choenamho/hi/lib/python3.10/site-packages/streamlit/elements/layouts.py", line 383, in columns
    return [row._block(column_proto(w / total_weight)) for w in weights]
  File "/Users/choenamho/hi/lib/python3.10/site-packages/streamlit/elements/layouts.py", line 383, in <listcomp>
    return [row._block(column_proto(w / total_weight)) for w in weights]
  File "/Users/choenamho/hi/lib/python3.10/site-packages/streamlit/delta_generator.py", line 518, in _block
    _check_nested_element_violation(self, block_type, ancestor_block_types)
  File "/Users/choenamho/hi/lib/python3.10/site-packages/streamlit/delta_generator.py", line 590, in _check_nested_element_violation
    raise StreamlitAPIException(
streamlit.errors.StreamlitAPIException: Columns can only be placed inside other columns up to one level of nesting.

ERROR:root:[auto_mall] 오류: Traceback (most recent call last):
  File "/Users/choenamho/Documents/GitHub/main-project/Home.py", line 67, in <module>
    import A_auto_mall as auto
  File "/Users/choenamho/Documents/GitHub/main-project/A_auto_mall.py", line 171
    st.session_state.current_page = "home"
    ^^
IndentationError: expected an indented block after 'if' statement on line 170

ERROR:root:[auto_mall] 오류: Traceback (most recent call last):
  File "/Users/choenamho/Documents/GitHub/main-project/Home.py", line 67, in <module>
    import A_auto_mall as auto
  File "/Users/choenamho/Documents/GitHub/main-project/A_auto_mall.py", line 171
    st.session_state.current_page = "home"
                                          ^
IndentationError: unindent does not match any outer indentation level

ERROR:root:[auto_mall] 오류: Traceback (most recent call last):
  File "/Users/choenamho/Documents/GitHub/main-project/Home.py", line 68, in <module>
    auto.app()
  File "/Users/choenamho/Documents/GitHub/main-project/A_auto_mall.py", line 125, in app
    cols = st.columns(3)
  File "/Users/choenamho/hi/lib/python3.10/site-packages/streamlit/runtime/metrics_util.py", line 410, in wrapped_func
    result = non_optional_func(*args, **kwargs)
  File "/Users/choenamho/hi/lib/python3.10/site-packages/streamlit/elements/layouts.py", line 383, in columns
    return [row._block(column_proto(w / total_weight)) for w in weights]
  File "/Users/choenamho/hi/lib/python3.10/site-packages/streamlit/elements/layouts.py", line 383, in <listcomp>
    return [row._block(column_proto(w / total_weight)) for w in weights]
  File "/Users/choenamho/hi/lib/python3.10/site-packages/streamlit/delta_generator.py", line 518, in _block
    _check_nested_element_violation(self, block_type, ancestor_block_types)
  File "/Users/choenamho/hi/lib/python3.10/site-packages/streamlit/delta_generator.py", line 590, in _check_nested_element_violation
    raise StreamlitAPIException(
streamlit.errors.StreamlitAPIException: Columns can only be placed inside other columns up to one level of nesting.

ERROR:root:[auto_mall] 오류: Traceback (most recent call last):
  File "/Users/choenamho/Documents/GitHub/main-project/Home.py", line 67, in <module>
    import A_auto_mall as auto
  File "/Users/choenamho/Documents/GitHub/main-project/A_auto_mall.py", line 171
    이름 = st.text_input("이름")
IndentationError: unexpected indent

ERROR:root:[auto_mall] 오류: Traceback (most recent call last):
  File "/Users/choenamho/Documents/GitHub/main-project/Home.py", line 67, in <module>
    import A_auto_mall as auto
  File "/Users/choenamho/Documents/GitHub/main-project/A_auto_mall.py", line 186
    with col_Auro_mall_2:
                         ^
IndentationError: expected an indented block after 'with' statement on line 186

ERROR:root:[auto_mall] 오류: Traceback (most recent call last):
  File "/Users/choenamho/Documents/GitHub/main-project/Home.py", line 67, in <module>
    import A_auto_mall as auto
  File "/Users/choenamho/Documents/GitHub/main-project/A_auto_mall.py", line 55
    with :
         ^
SyntaxError: invalid syntax

ERROR:root:[auto_mall] 오류: Traceback (most recent call last):
  File "/Users/choenamho/Documents/GitHub/main-project/Home.py", line 67, in <module>
    import A_auto_mall as auto
  File "/Users/choenamho/Documents/GitHub/main-project/A_auto_mall.py", line 55
    withcol1:
             ^
SyntaxError: invalid syntax

ERROR:root:[auto_mall] 오류: Traceback (most recent call last):
  File "/Users/choenamho/Documents/GitHub/main-project/Home.py", line 67, in <module>
    import A_auto_mall as auto
  File "/Users/choenamho/Documents/GitHub/main-project/A_auto_mall.py", line 55
    col1:
         ^
SyntaxError: invalid syntax

ERROR:root:[auto_mall] 오류: Traceback (most recent call last):
  File "/Users/choenamho/Documents/GitHub/main-project/Home.py", line 67, in <module>
    import A_auto_mall as auto
  File "/Users/choenamho/Documents/GitHub/main-project/A_auto_mall.py", line 172, in <module>
    with col_side:
NameError: name 'col_side' is not defined

ERROR:root:[auto_mall] 오류: Traceback (most recent call last):
  File "/Users/choenamho/Documents/GitHub/main-project/Home.py", line 67, in <module>
    import A_auto_mall as auto
  File "/Users/choenamho/Documents/GitHub/main-project/A_auto_mall.py", line 59
    tabs = st.tabs([
    ^^^^
IndentationError: expected an indented block after 'with' statement on line 58

ERROR:root:[auto_mall] 오류: Traceback (most recent call last):
  File "/Users/choenamho/Documents/GitHub/main-project/Home.py", line 67, in <module>
    import A_auto_mall as auto
  File "/Users/choenamho/Documents/GitHub/main-project/A_auto_mall.py", line 171, in <module>
    with col_side:
NameError: name 'col_side' is not defined

ERROR:root:[auto_mall] 오류: Traceback (most recent call last):
  File "/Users/choenamho/Documents/GitHub/main-project/Home.py", line 67, in <module>
    import A_auto_mall as auto
  File "/Users/choenamho/Documents/GitHub/main-project/A_auto_mall.py", line 171, in <module>
    with col_side:
NameError: name 'col_side' is not defined

ERROR:root:[auto_mall] 오류: Traceback (most recent call last):
  File "/Users/choenamho/Documents/GitHub/main-project/Home.py", line 68, in <module>
    auto.app()
  File "/Users/choenamho/Documents/GitHub/main-project/A_auto_mall.py", line 186, in app
    with col_side:
NameError: name 'col_side' is not defined

ERROR:root:[auto_mall] 오류: Traceback (most recent call last):
  File "/Users/choenamho/Documents/GitHub/main-project/Home.py", line 68, in <module>
    auto.app()
  File "/Users/choenamho/Documents/GitHub/main-project/A_auto_mall.py", line 113, in app
    cols = st.columns(3)
  File "/Users/choenamho/hi/lib/python3.10/site-packages/streamlit/runtime/metrics_util.py", line 410, in wrapped_func
    result = non_optional_func(*args, **kwargs)
  File "/Users/choenamho/hi/lib/python3.10/site-packages/streamlit/elements/layouts.py", line 383, in columns
    return [row._block(column_proto(w / total_weight)) for w in weights]
  File "/Users/choenamho/hi/lib/python3.10/site-packages/streamlit/elements/layouts.py", line 383, in <listcomp>
    return [row._block(column_proto(w / total_weight)) for w in weights]
  File "/Users/choenamho/hi/lib/python3.10/site-packages/streamlit/delta_generator.py", line 518, in _block
    _check_nested_element_violation(self, block_type, ancestor_block_types)
  File "/Users/choenamho/hi/lib/python3.10/site-packages/streamlit/delta_generator.py", line 590, in _check_nested_element_violation
    raise StreamlitAPIException(
streamlit.errors.StreamlitAPIException: Columns can only be placed inside other columns up to one level of nesting.

ERROR:root:[auto_mall] 오류: Traceback (most recent call last):
  File "/Users/choenamho/Documents/GitHub/main-project/Home.py", line 67, in <module>
    import A_auto_mall as auto
  File "/Users/choenamho/Documents/GitHub/main-project/A_auto_mall.py", line 168
    
    ^
IndentationError: expected an indented block after 'with' statement on line 166

ERROR:root:[auto_mall] 오류: Traceback (most recent call last):
  File "/Users/choenamho/Documents/GitHub/main-project/Home.py", line 67, in <module>
    import A_auto_mall as auto
  File "/Users/choenamho/Documents/GitHub/main-project/A_auto_mall.py", line 170
    with st.sidebar:
    ^^^^
IndentationError: expected an indented block after 'with' statement on line 166

ERROR:root:[auto_mall] 오류: Traceback (most recent call last):
  File "/Users/choenamho/Documents/GitHub/main-project/Home.py", line 67, in <module>
    import A_auto_mall as auto
  File "/Users/choenamho/Documents/GitHub/main-project/A_auto_mall.py", line 171
    with st.sidebar:
    ^^^^
IndentationError: expected an indented block after 'with' statement on line 167

ERROR:root:[auto_mall] 오류: Traceback (most recent call last):
  File "/Users/choenamho/Documents/GitHub/main-project/Home.py", line 67, in <module>
    import A_auto_mall as auto
  File "/Users/choenamho/Documents/GitHub/main-project/A_auto_mall.py", line 152
    with st.sidebar:
    ^^^^
IndentationError: expected an indented block after 'with' statement on line 148

ERROR:root:[auto_mall] 오류: Traceback (most recent call last):
  File "/Users/choenamho/Documents/GitHub/main-project/Home.py", line 67, in <module>
    import A_auto_mall as auto
  File "/Users/choenamho/Documents/GitHub/main-project/A_auto_mall.py", line 94
    col2, col3 = st.columns([3,1])
IndentationError: unexpected indent

ERROR:root:[auto_mall] 오류: Traceback (most recent call last):
  File "/Users/choenamho/Documents/GitHub/main-project/Home.py", line 67, in <module>
    import A_auto_mall as auto
  File "/Users/choenamho/Documents/GitHub/main-project/A_auto_mall.py", line 198
    st.markdown("### 고객 정보 입력")
IndentationError: unexpected indent

ERROR:root:[auto_mall] 오류: Traceback (most recent call last):
  File "/Users/choenamho/Documents/GitHub/main-project/Home.py", line 67, in <module>
    import A_auto_mall as auto
  File "/Users/choenamho/Documents/GitHub/main-project/A_auto_mall.py", line 186
    입력이름 = st.text_input("상담자 이름을 입력하세요")
IndentationError: expected an indented block after 'if' statement on line 185

ERROR:root:[auto_mall] 오류: Traceback (most recent call last):
  File "/Users/choenamho/Documents/GitHub/main-project/Home.py", line 67, in <module>
    import A_auto_mall as auto
  File "/Users/choenamho/Documents/GitHub/main-project/A_auto_mall.py", line 180
    df_employees = load_employees()
IndentationError: expected an indented block after 'with' statement on line 179

